Workbook

Sheet 요약_대시보드
A1: 한솔주공5단지 리모델링 투자수익 계산기
A2: 노랑칸=직접 입력 / 회색=자동계산 / 초록=핵심결과 · 단위 [억원] · 작성 2026-06
A4: ■ 1. 거래 대상 (타입 선택)
A5: 선택 타입 | B5: D5 | C5: 드롭다운 ▼ (타입별_비교 시트 참고)
A6: 전용면적 | B6: =VLOOKUP($B$5,타입별_비교!$A$4:$O$12,2,0) | C6: 리모델링 후 전용
A7: 공급면적 | B7: =VLOOKUP($B$5,타입별_비교!$A$4:$O$12,3,0)
A8: 공급 평형 | B8: =B7/3.3058 | C8: ← 가치산정 기준 평수
A9: 구조 | B9: =VLOOKUP($B$5,타입별_비교!$A$4:$O$12,5,0)
A11: ■ 2. 자금 조달
A12: 죽전벽산 매도순수입 | B12: 10.5 | C12: 기존대출·비용 차감 후 손에 쥐는 현금
A13: 보유 현금 | B13: 3 | C13: ※ "현금 총 3억" 해석에 맞게 조정
A14: 주택담보대출 | B14: 4 | C14: 신규 주담대 한도
A15: 주담대 금리(연) | B15: 0.04 | C15: 변동 가정 → 민감도 시트
A16: 총 동원자금 | B16: =B12+B13+B14 | C16: 현금 13.5 + 대출 = 동원가능
A18: ■ 3. 취득 비용
A19: 입주권 매입가(호가) | B19: 14.5 | C19: 실제 협상가 입력
A20: 취득세율(매입) | B20: 0.035 | C20: 9억초과 주택 ≈3.3~3.5%
A21: 취득세(매입) | B21: =B19*B20
A22: 중개수수료율 | B22: 0.005 | C22: 상한 0.7% 이내
A23: 중개수수료 | B23: =B19*B22
A24: 기타 취득부대비 | B24: 0.1 | C24: 법무·등기·이사 등
A25: 취득단계 소계 | B25: =B19+B21+B23+B24
A27: ■ 4. 리모델링 분담금
A28: 기본 분담금(타입) | B28: =VLOOKUP($B$5,타입별_비교!$A$4:$O$12,7,0) | C28: 리모델링정보 원본
A29: 분담금 증액률 | B29: 0.1 | C29: ★공사비 상승 → 향후 증가 가정
A30: 적용 분담금 | B30: =B28*(1+B29)
A31: 완공취득세율(증가분) | B31: 0.03 | C31: 리모델링 증가면적 원시취득세 근사
A32: 완공 취득세 | B32: =B30*B31
A34: ■ 5. 보유비용 (공사·대기 기간)
A35: 공사·대기 기간(개월) | B35: 30 | C35: 입주권 매수~완공 입주까지
A36: 월세(만원/월) | B36: 180 | C36: 집 판 뒤 대기 거주비 ★
A37: 월세 상승률(연) | B37: 0.03
A38: 누적 월세 | B38: =IF(B37=0,B36/10000*B35,B36/10000*(((1+B37/12)^B35-1)/(B37/12))) | C38: 상승률 반영 누적
A39: 주담대 누적이자 | B39: =B14*B15*(B35/12)
A40: 분담금/이주비대출 이자 | B40: 0 | C40: 분담금 대출 시 이자(선택)
A41: 연 보유세(만원) | B41: 150 | C41: 재산세+종부세 추정
A42: 누적 보유세 | B42: =B41/10000*(B35/12)
A43: 보유비용 소계 | B43: =B38+B39+B40+B42
A45: ■ 6. 완공 후 가치
A46: 완공 평당가(공급평,만원) | B46: 7000 | C46: ★최대변수★ 더샵센트로≈6,400 / 티에르원≈7,460
...

Sheet 시나리오_민감도
A1: ■ 시나리오 & 민감도 분석 (선택 타입 기준, 대시보드 입력 연동)
A2: ※ 행/열 머리값을 바꾸면 자동 재계산. 음수(손실)=빨강
A4: [A] 완공평당가 시나리오
A5: 구분 | B5: 비관(더샵급) | C5: 기본 | D5: 낙관(티에르원↑) | E5: 초낙관(+물가)
A6: 완공평당가(만원) | B6: 6400 | C6: 7000 | D6: 7600 | E6: 8200
A7: 완공가치 | B7: =요약_대시보드!$B$8*B$6/10000 | C7: =요약_대시보드!$B$8*C$6/10000 | D7: =요약_대시보드!$B$8*D$6/10000 | E7: =요약_대시보드!$B$8*E$6/10000
A8: 총투입원가 | B8: =요약_대시보드!$B$50 | C8: =요약_대시보드!$B$50 | D8: =요약_대시보드!$B$50 | E8: =요약_대시보드!$B$50
A9: 평가손익 | B9: =B7-B8 | C9: =C7-C8 | D9: =D7-D8 | E9: =E7-E8
A10: 총투입수익률 | B10: =B9/B8 | C10: =C9/C8 | D10: =D9/D8 | E10: =E9/E8
A11: ROE | B11: =B9/요약_대시보드!$B$51 | C11: =C9/요약_대시보드!$B$51 | D11: =D9/요약_대시보드!$B$51 | E11: =E9/요약_대시보드!$B$51
A14: [B] 민감도: 완공평당가(↓) × 분담금증액(→) → 평가손익(억)
A15: 평당가＼증액 | B15: 0 | C15: 0.1 | D15: 0.2 | E15: 0.3
A16: 6400 | B16: =요약_대시보드!$B$8*$A16/10000-(요약_대시보드!$B$25+요약_대시보드!$B$28*(1+B$15)*(1+요약_대시보드!$B$31)+요약_대시보드!$B$43) | C16: =요약_대시보드!$B$8*$A16/10000-(요약_대시보드!$B$25+요약_대시보드!$B$28*(1+C$15)*(1+요약_대시보드!$B$31)+요약_대시보드!$B$43) | D16: =요약_대시보드!$B$8*$A16/10000-(요약_대시보드!$B$25+요약_대시보드!$B$28*(1+D$15)*(1+요약_대시보드!$B$31)+요약_대시보드!$B$43) | E16: =요약_대시보드!$B$8*$A16/10000-(요약_대시보드!$B$25+요약_대시보드!$B$28*(1+E$15)*(1+요약_대시보드!$B$31)+요약_대시보드!$B$43)
A17: 6800 | B17: =요약_대시보드!$B$8*$A17/10000-(요약_대시보드!$B$25+요약_대시보드!$B$28*(1+B$15)*(1+요약_대시보드!$B$31)+요약_대시보드!$B$43) | C17: =요약_대시보드!$B$8*$A17/10000-(요약_대시보드!$B$25+요약_대시보드!$B$28*(1+C$15)*(1+요약_대시보드!$B$31)+요약_대시보드!$B$43) | D17: =요약_대시보드!$B$8*$A17/10000-(요약_대시보드!$B$25+요약_대시보드!$B$28*(1+D$15)*(1+요약_대시보드!$B$31)+요약_대시보드!$B$43) | E17: =요약_대시보드!$B$8*$A17/10000-(요약_대시보드!$B$25+요약_대시보드!$B$28*(1+E$15)*(1+요약_대시보드!$B$31)+요약_대시보드!$B$43)
A18: 7200 | B18: =요약_대시보드!$B$8*$A18/10000-(요약_대시보드!$B$25+요약_대시보드!$B$28*(1+B$15)*(1+요약_대시보드!$B$31)+요약_대시보드!$B$43) | C18: =요약_대시보드!$B$8*$A18/10000-(요약_대시보드!$B$25+요약_대시보드!$B$28*(1+C$15)*(1+요약_대시보드!$B$31)+요약_대시보드!$B$43) | D18: =요약_대시보드!$B$8*$A18/10000-(요약_대시보드!$B$25+요약_대시보드!$B$28*(1+D$15)*(1+요약_대시보드!$B$31)+요약_대시보드!$B$43) | E18: =요약_대시보드!$B$8*$A18/10000-(요약_대시보드!$B$25+요약_대시보드!$B$28*(1+E$15)*(1+요약_대시보드!$B$31)+요약_대시보드!$B$43)
A19: 7600 | B19: =요약_대시보드!$B$8*$A19/10000-(요약_대시보드!$B$25+요약_대시보드!$B$28*(1+B$15)*(1+요약_대시보드!$B$31)+요약_대시보드!$B$43) | C19: =요약_대시보드!$B$8*$A19/10000-(요약_대시보드!$B$25+요약_대시보드!$B$28*(1+C$15)*(1+요약_대시보드!$B$31)+요약_대시보드!$B$43) | D19: =요약_대시보드!$B$8*$A19/10000-(요약_대시보드!$B$25+요약_대시보드!$B$28*(1+D$15)*(1+요약_대시보드!$B$31)+요약_대시보드!$B$43) | E19: =요약_대시보드!$B$8*$A19/10000-(요약_대시보드!$B$25+요약_대시보드!$B$28*(1+E$15)*(1+요약_대시보드!$B$31)+요약_대시보드!$B$43)
A20: 8000 | B20: =요약_대시보드!$B$8*$A20/10000-(요약_대시보드!$B$25+요약_대시보드!$B$28*(1+B$15)*(1+요약_대시보드!$B$31)+요약_대시보드!$B$43) | C20: =요약_대시보드!$B$8*$A20/10000-(요약_대시보드!$B$25+요약_대시보드!$B$28*(1+C$15)*(1+요약_대시보드!$B$31)+요약_대시보드!$B$43) | D20: =요약_대시보드!$B$8*$A20/10000-(요약_대시보드!$B$25+요약_대시보드!$B$28*(1+D$15)*(1+요약_대시보드!$B$31)+요약_대시보드!$B$43) | E20: =요약_대시보드!$B$8*$A20/10000-(요약_대시보드!$B$25+요약_대시보드!$B$28*(1+E$15)*(1+요약_대시보드!$B$31)+요약_대시보드!$B$43)
A21: 8400 | B21: =요약_대시보드!$B$8*$A21/10000-(요약_대시보드!$B$25+요약_대시보드!$B$28*(1+B$15)*(1+요약_대시보드!$B$31)+요약_대시보드!$B$43) | C21: =요약_대시보드!$B$8*$A21/10000-(요약_대시보드!$B$25+요약_대시보드!$B$28*(1+C$15)*(1+요약_대시보드!$B$31)+요약_대시보드!$B$43) | D21: =요약_대시보드!$B$8*$A21/10000-(요약_대시보드!$B$25+요약_대시보드!$B$28*(1+D$15)*(1+요약_대시보드!$B$31)+요약_대시보드!$B$43) | E21: =요약_대시보드!$B$8*$A21/10000-(요약_대시보드!$B$25+요약_대시보드!$B$28*(1+E$15)*(1+요약_대시보드!$B$31)+요약_대시보드!$B$43)
A24: [C] 민감도: 월세(↓) × 주담대금리(→) → 보유비용 합계(억)
A25: 월세＼금리 | B25: 0.03 | C25: 0.04 | D25: 0.05 | E25: 0.06
A26: 120 | B26: =IF(요약_대시보드!$B$37=0,$A26/10000*요약_대시보드!$B$35,$A26/10000*(((1+요약_대시보드!$B$37/12)^요약_대시보드!$B$35-1)/(요약_대시보드!$B$37/12)))+요약_대시보드!$B$14*B$25*(요약_대시보드!$B$35/12)+요약_대시보드!$B$41/10000*(요약_대시보드!$B$35/12) | C26: =IF(요약_대시보드!$B$37=0,$A26/10000*요약_대시보드!$B$35,$A26/10000*(((1+요약_대시보드!$B$37/12)^요약_대시보드!$B$35-1)/(요약_대시보드!$B$37/12)))+요약_대시보드!$B$14*C$25*(요약_대시보드!$B$35/12)+요약_대시보드!$B$41/10000*(요약_대시보드!$B$35/12) | D26: =IF(요약_대시보드!$B$37=0,$A26/10000*요약_대시보드!$B$35,$A26/10000*(((1+요약_대시보드!$B$37/12)^요약_대시보드!$B$35-1)/(요약_대시보드!$B$37/12)))+요약_대시보드!$B$14*D$25*(요약_대시보드!$B$35/12)+요약_대시보드!$B$41/10000*(요약_대시보드!$B$35/12) | E26: =IF(요약_대시보드!$B$37=0,$A26/10000*요약_대시보드!$B$35,$A26/10000*(((1+요약_대시보드!$B$37/12)^요약_대시보드!$B$35-1)/(요약_대시보드!$B$37/12)))+요약_대시보드!$B$14*E$25*(요약_대시보드!$B$35/12)+요약_대시보드!$B$41/10000*(요약_대시보드!$B$35/12)
A27: 150 | B27: =IF(요약_대시보드!$B$37=0,$A27/10000*요약_대시보드!$B$35,$A27/10000*(((1+요약_대시보드!$B$37/12)^요약_대시보드!$B$35-1)/(요약_대시보드!$B$37/12)))+요약_대시보드!$B$14*B$25*(요약_대시보드!$B$35/12)+요약_대시보드!$B$41/10000*(요약_대시보드!$B$35/12) | C27: =IF(요약_대시보드!$B$37=0,$A27/10000*요약_대시보드!$B$35,$A27/10000*(((1+요약_대시보드!$B$37/12)^요약_대시보드!$B$35-1)/(요약_대시보드!$B$37/12)))+요약_대시보드!$B$14*C$25*(요약_대시보드!$B$35/12)+요약_대시보드!$B$41/10000*(요약_대시보드!$B$35/12) | D27: =IF(요약_대시보드!$B$37=0,$A27/10000*요약_대시보드!$B$35,$A27/10000*(((1+요약_대시보드!$B$37/12)^요약_대시보드!$B$35-1)/(요약_대시보드!$B$37/12)))+요약_대시보드!$B$14*D$25*(요약_대시보드!$B$35/12)+요약_대시보드!$B$41/10000*(요약_대시보드!$B$35/12) | E27: =IF(요약_대시보드!$B$37=0,$A27/10000*요약_대시보드!$B$35,$A27/10000*(((1+요약_대시보드!$B$37/12)^요약_대시보드!$B$35-1)/(요약_대시보드!$B$37/12)))+요약_대시보드!$B$14*E$25*(요약_대시보드!$B$35/12)+요약_대시보드!$B$41/10000*(요약_대시보드!$B$35/12)
A28: 180 | B28: =IF(요약_대시보드!$B$37=0,$A28/10000*요약_대시보드!$B$35,$A28/10000*(((1+요약_대시보드!$B$37/12)^요약_대시보드!$B$35-1)/(요약_대시보드!$B$37/12)))+요약_대시보드!$B$14*B$25*(요약_대시보드!$B$35/12)+요약_대시보드!$B$41/10000*(요약_대시보드!$B$35/12) | C28: =IF(요약_대시보드!$B$37=0,$A28/10000*요약_대시보드!$B$35,$A28/10000*(((1+요약_대시보드!$B$37/12)^요약_대시보드!$B$35-1)/(요약_대시보드!$B$37/12)))+요약_대시보드!$B$14*C$25*(요약_대시보드!$B$35/12)+요약_대시보드!$B$41/10000*(요약_대시보드!$B$35/12) | D28: =IF(요약_대시보드!$B$37=0,$A28/10000*요약_대시보드!$B$35,$A28/10000*(((1+요약_대시보드!$B$37/12)^요약_대시보드!$B$35-1)/(요약_대시보드!$B$37/12)))+요약_대시보드!$B$14*D$25*(요약_대시보드!$B$35/12)+요약_대시보드!$B$41/10000*(요약_대시보드!$B$35/12) | E28: =IF(요약_대시보드!$B$37=0,$A28/10000*요약_대시보드!$B$35,$A28/10000*(((1+요약_대시보드!$B$37/12)^요약_대시보드!$B$35-1)/(요약_대시보드!$B$37/12)))+요약_대시보드!$B$14*E$25*(요약_대시보드!$B$35/12)+요약_대시보드!$B$41/10000*(요약_대시보드!$B$35/12)
A29: 210 | B29: =IF(요약_대시보드!$B$37=0,$A29/10000*요약_대시보드!$B$35,$A29/10000*(((1+요약_대시보드!$B$37/12)^요약_대시보드!$B$35-1)/(요약_대시보드!$B$37/12)))+요약_대시보드!$B$14*B$25*(요약_대시보드!$B$35/12)+요약_대시보드!$B$41/10000*(요약_대시보드!$B$35/12) | C29: =IF(요약_대시보드!$B$37=0,$A29/10000*요약_대시보드!$B$35,$A29/10000*(((1+요약_대시보드!$B$37/12)^요약_대시보드!$B$35-1)/(요약_대시보드!$B$37/12)))+요약_대시보드!$B$14*C$25*(요약_대시보드!$B$35/12)+요약_대시보드!$B$41/10000*(요약_대시보드!$B$35/12) | D29: =IF(요약_대시보드!$B$37=0,$A29/10000*요약_대시보드!$B$35,$A29/10000*(((1+요약_대시보드!$B$37/12)^요약_대시보드!$B$35-1)/(요약_대시보드!$B$37/12)))+요약_대시보드!$B$14*D$25*(요약_대시보드!$B$35/12)+요약_대시보드!$B$41/10000*(요약_대시보드!$B$35/12) | E29: =IF(요약_대시보드!$B$37=0,$A29/10000*요약_대시보드!$B$35,$A29/10000*(((1+요약_대시보드!$B$37/12)^요약_대시보드!$B$35-1)/(요약_대시보드!$B$37/12)))+요약_대시보드!$B$14*E$25*(요약_대시보드!$B$35/12)+요약_대시보드!$B$41/10000*(요약_대시보드!$B$35/12)
A30: 240 | B30: =IF(요약_대시보드!$B$37=0,$A30/10000*요약_대시보드!$B$35,$A30/10000*(((1+요약_대시보드!$B$37/12)^요약_대시보드!$B$35-1)/(요약_대시보드!$B$37/12)))+요약_대시보드!$B$14*B$25*(요약_대시보드!$B$35/12)+요약_대시보드!$B$41/10000*(요약_대시보드!$B$35/12) | C30: =IF(요약_대시보드!$B$37=0,$A30/10000*요약_대시보드!$B$35,$A30/10000*(((1+요약_대시보드!$B$37/12)^요약_대시보드!$B$35-1)/(요약_대시보드!$B$37/12)))+요약_대시보드!$B$14*C$25*(요약_대시보드!$B$35/12)+요약_대시보드!$B$41/10000*(요약_대시보드!$B$35/12) | D30: =IF(요약_대시보드!$B$37=0,$A30/10000*요약_대시보드!$B$35,$A30/10000*(((1+요약_대시보드!$B$37/12)^요약_대시보드!$B$35-1)/(요약_대시보드!$B$37/12)))+요약_대시보드!$B$14*D$25*(요약_대시보드!$B$35/12)+요약_대시보드!$B$41/10000*(요약_대시보드!$B$35/12) | E30: =IF(요약_대시보드!$B$37=0,$A30/10000*요약_대시보드!$B$35,$A30/10000*(((1+요약_대시보드!$B$37/12)^요약_대시보드!$B$35-1)/(요약_대시보드!$B$37/12)))+요약_대시보드!$B$14*E$25*(요약_대시보드!$B$35/12)+요약_대시보드!$B$41/10000*(요약_대시보드!$B$35/12)
A33: ※ [C]는 보유비용(비용이므로 작을수록 유리)이고 [A][B]는 평가손익(클수록 유리). 완공평당가가 손익분기(대시보드 B61)를 넘어야 이익.

Sheet 타입별_비교
A1: ■ 리모델링 타입별 투자성 비교 (BEP 평당가 낮을수록 우수)
A2: ※ 회색=리모델링정보 시트 원본 / 노랑=대표호가(편집) / 초록=대시보드 가정 반영 자동계산
A3: 타입 | B3: 전용㎡ | C3: 공급㎡ | D3: 공급평 | E3: 구조 | F3: 가능동 | G3: 기본분담금 | H3: 대표매입호가 | I3: 적용분담금 | J3: 입주총원가 | K3: 총투입(올인) | L3: 완공가치 | M3: 평가손익 | N3: 수익률 | O3: BEP평당가(만원)
A4: D3 | B4: 72.11 | C4: 102.63 | D4: =C4/3.3058 | E4: 방3/화2/복층형 | F4: 510동 2·7·8호 | G4: 3.8301129 | H4: 14.8 | I4: =G4*(1+요약_대시보드!$B$29) | J4: =H4+I4 | K4: =H4*(1+요약_대시보드!$B$20+요약_대시보드!$B$22)+요약_대시보드!$B$24+I4*(1+요약_대시보드!$B$31)+요약_대시보드!$B$43 | L4: =D4*요약_대시보드!$B$46/10000 | M4: =L4-K4 | N4: =M4/K4 | O4: =K4*10000/D4
A5: D5 | B5: 65.86 | C5: 93.6 | D5: =C5/3.3058 | E5: 방3/화2 | F5: 510동 1호 | G5: 3.4054891 | H5: 14.5 | I5: =G5*(1+요약_대시보드!$B$29) | J5: =H5+I5 | K5: =H5*(1+요약_대시보드!$B$20+요약_대시보드!$B$22)+요약_대시보드!$B$24+I5*(1+요약_대시보드!$B$31)+요약_대시보드!$B$43 | L5: =D5*요약_대시보드!$B$46/10000 | M5: =L5-K5 | N5: =M5/K5 | O5: =K5*10000/D5
A6: D6 | B6: 56.17 | C6: 79.83 | D6: =C6/3.3058 | E6: 방3/화1 | F6: 509동 2호 | G6: 1.901817 | H6: 14.3 | I6: =G6*(1+요약_대시보드!$B$29) | J6: =H6+I6 | K6: =H6*(1+요약_대시보드!$B$20+요약_대시보드!$B$22)+요약_대시보드!$B$24+I6*(1+요약_대시보드!$B$31)+요약_대시보드!$B$43 | L6: =D6*요약_대시보드!$B$46/10000 | M6: =L6-K6 | N6: =M6/K6 | O6: =K6*10000/D6
A7: D7 | B7: 65.72 | C7: 93.4 | D7: =C7/3.3058 | E7: 방3/화2 | F7: 504동1호/509동1호 | G7: 3.499117 | H7: 14.5 | I7: =G7*(1+요약_대시보드!$B$29) | J7: =H7+I7 | K7: =H7*(1+요약_대시보드!$B$20+요약_대시보드!$B$22)+요약_대시보드!$B$24+I7*(1+요약_대시보드!$B$31)+요약_대시보드!$B$43 | L7: =D7*요약_대시보드!$B$46/10000 | M7: =L7-K7 | N7: =M7/K7 | O7: =K7*10000/D7
A8: AB1 | B8: 58.49 | C8: 83.13 | D8: =C8/3.3058 | E8: 방3/화2 | F8: 515동 1호(신축) | G8: 4.2651341 | H8: 14.7 | I8: =G8*(1+요약_대시보드!$B$29) | J8: =H8+I8 | K8: =H8*(1+요약_대시보드!$B$20+요약_대시보드!$B$22)+요약_대시보드!$B$24+I8*(1+요약_대시보드!$B$31)+요약_대시보드!$B$43 | L8: =D8*요약_대시보드!$B$46/10000 | M8: =L8-K8 | N8: =M8/K8 | O8: =K8*10000/D8
A9: AB2 | B9: 58.48 | C9: 83.11 | D9: =C9/3.3058 | E9: 방3/화2 | F9: 515동 2호(신축) | G9: 4.5662704 | H9: 14.7 | I9: =G9*(1+요약_대시보드!$B$29) | J9: =H9+I9 | K9: =H9*(1+요약_대시보드!$B$20+요약_대시보드!$B$22)+요약_대시보드!$B$24+I9*(1+요약_대시보드!$B$31)+요약_대시보드!$B$43 | L9: =D9*요약_대시보드!$B$46/10000 | M9: =L9-K9 | N9: =M9/K9 | O9: =K9*10000/D9
A10: C3 | B10: 59.45 | C10: 84.49 | D10: =C10/3.3058 | E10: 방3/화2 | F10: 503동3호/512동3호 | G10: 3.7692921 | H10: 14.5 | I10: =G10*(1+요약_대시보드!$B$29) | J10: =H10+I10 | K10: =H10*(1+요약_대시보드!$B$20+요약_대시보드!$B$22)+요약_대시보드!$B$24+I10*(1+요약_대시보드!$B$31)+요약_대시보드!$B$43 | L10: =D10*요약_대시보드!$B$46/10000 | M10: =L10-K10 | N10: =M10/K10 | O10: =K10*10000/D10
A11: C4 | B11: 59.72 | C11: 84.87 | D11: =C11/3.3058 | E11: 방3/화2 | F11: 513동 2·3호 | G11: 4.3012045 | H11: 14.8 | I11: =G11*(1+요약_대시보드!$B$29) | J11: =H11+I11 | K11: =H11*(1+요약_대시보드!$B$20+요약_대시보드!$B$22)+요약_대시보드!$B$24+I11*(1+요약_대시보드!$B$31)+요약_대시보드!$B$43 | L11: =D11*요약_대시보드!$B$46/10000 | M11: =L11-K11 | N11: =M11/K11 | O11: =K11*10000/D11
A12: C5 | B12: 59.23 | C12: 84.18 | D12: =C12/3.3058 | E12: 방3/화2 | F12: 513동 1·4호 | G12: 4.218517 | H12: 14.5 | I12: =G12*(1+요약_대시보드!$B$29) | J12: =H12+I12 | K12: =H12*(1+요약_대시보드!$B$20+요약_대시보드!$B$22)+요약_대시보드!$B$24+I12*(1+요약_대시보드!$B$31)+요약_대시보드!$B$43 | L12: =D12*요약_대시보드!$B$46/10000 | M12: =L12-K12 | N12: =M12/K12 | O12: =K12*10000/D12
A14: ▶ 해석: 공급면적 "84"라도 전용은 59㎡(25평)인 C·AB타입은 분담금이 높아 BEP 평당가 8,000만↑ → 불리. D타입(특히 D3 복층 31평)이 면적 대비 분담금이 낮아 BEP 6,700~7,100만으로 가장 유리.

Sheet 매물
A1: 동 | B1: 층 | C1: 호가 | D1: 변경타입 | E1: 기타조건 | G1: ※ 변경타입의 분담금/면적은 [리모델링정보] 시트, 투자성은 [타입별_비교] 참고
A2: 510 | B2: 15 | C2: 1480000000 | D2: D5 | E2: 남향
A3: 510 | B3: 11 | C3: 1480000000 | D3: AB1 or AB2 | E3: 남향
A4: 512 | B4: 25 | C4: 1450000000 | D4: C5 | E4: 정남향/이주비대출
A5: 510 | B5: 6 | C5: 1500000000 | D5: D5 | E5: 정남향
A6: 503 | B6: 17 | C6: 1480000000 | D6: C4 | E6: 정남향
A7: 509 | B7: 13 | C7: 1450000000 | D7: D7
A8: 512 | B8: 16 | C8: 1450000000 | D8: C5 | E8: 남향
A9: 510 | B9: 4 | C9: 1470000000 | D9: AB1 or AB2 | E9: 남향
A10: 510 | B10: 5 | C10: 1450000000 | D10: D5

Sheet 리모델링정보
A1: 매물 | B1: 분담금 | C1: 전용면적 | D1: 공급면적 | E1: 구조 | F1: 가능동
A2: D3 | B2: 383011291 | C2: 72.11 | D2: 102.63 | E2: 방3/화2/복층형 | F2: 510동 2호,7호,8호
A3: D5 | B3: 340548910 | C3: 65.86 | D3: 93.6 | E3: 방3/화2 | F3: 510동 1호
A4: D6 | B4: 190181700 | C4: 56.17 | D4: 79.83 | E4: 방3/화1 | F4: 509동 2호
A5: D7 | B5: 349911700 | C5: 65.72 | D5: 93.4 | E5: 방3/화2 | F5: 504동 1호/509동 1호
A6: AB1 | B6: 426513407 | C6: 58.49 | D6: 83.13 | E6: 방3/화2 | F6: 515동 1호(신축)
A7: AB2 | B7: 456627043 | C7: 58.48 | D7: 83.11 | E7: 방3/화2 | F7: 515동 2호(신축)
A8: C3 | B8: 376929211 | C8: 59.45 | D8: 84.49 | E8: 방3/화2 | F8: 503동 3호/512동 3호
A9: C4 | B9: 430120452 | C9: 59.72 | D9: 84.87 | E9: 방3/화2 | F9: 513동 2호,3호
A10: C5 | B10: 421851702 | C10: 59.23 | D10: 84.18 | E10: 방3/화2 | F10: 513동 1호,4호

Sheet 분당티에르원
A1: 타입 | B1: 분양가
A2: 66 | B2: 1974000000
A3: 74 | B3: 2318000000
A4: 84A | B4: 2532000000
A5: 84A1-1 | B5: 2509000000
A6: 84A1-5 | B6: 2502000000
A7: 84A4-1 | B7: 2567000000
A8: 84A4-2 | B8: 2670000000
A9: 84A6 | B9: 2684000000

Sheet 더샵센트로
A1: 타입 | B1: 분양가
A2: 60A | B2: 1490000000
A3: 60C | B3: 1492000000
A4: 64A | B4: 1640000000
A5: 71D | B5: 1822000000
A6: 73B1 | B6: 1883000000
A7: 73B2 | B7: 1833000000
A8: 78N | B8: 1997000000
A9: 84N | B9: 2180000000
